<?xml version="1.0"?>
<sdf version="1.6">
    <model name="x1">
        <static>0</static>
        <link name="base_link">
            <inertial>
                <pose frame="">0.0 0.0 0.062 0 0 0</pose>
                <mass>46.034</mass>
                <inertia>
                    <ixx>0.613201</ixx>
                    <ixy>-0.0236401</ixy>
                    <ixz>-0.1197</ixz>
                    <iyy>1.7496</iyy>
                    <iyz>-0.00154411</iyz>
                    <izz>2.0406</izz>
                </inertia>
            </inertial>
            <collision name="base_link_collision">
                <pose frame="">0 0 0.12 0 0 0</pose>
                <geometry>
                    <box>
                        <size>0.9874 0.5709 0.05</size>
                    </box>
                </geometry>
            </collision>
            <collision name="base_link_collision_bottom">
                <pose frame="">0 0 0.046 0 0 0</pose>
                <geometry>
                    <box>
                        <size>0.80 0.5709 0.095</size>
                    </box>
                </geometry>
            </collision>
            <collision name="base_link_collision_1">
                <pose frame="">0 0 0.185625 0 0 0</pose>
                <geometry>
                    <box>
                        <size>0.78992 0.5709 0.12375</size>
                    </box>
                </geometry>
            </collision>
            <collision name="top_plate_collision">
                <pose frame="">0.0812 0 0.245 0 0 0</pose>
                <geometry>
                    <mesh>
                        <uri>meshes/top_plate.dae</uri>
                    </mesh>
                </geometry>
            </collision>
            <collision name="top_plate_collision_2">
                <pose frame="">0.0812 0 0.245 0 0 0</pose>
                <geometry>
                    <box>
                        <size>0.32 0.41 0.09</size>
                    </box>
                </geometry>
            </collision>
            <visual name="base_link_visual">
                <pose frame="">0 0 0 0 0 -3.14159</pose>
                <geometry>
                    <mesh>
                        <uri>meshes/chassis.dae</uri>
                    </mesh>
                </geometry>
            </visual>
            <visual name="center_left_headlight_visual">
                <pose frame="">0.485766 0.0844 0.124431 0 0 -3.14159</pose>
                <geometry>
                    <mesh>
                        <uri>meshes/headlight.dae</uri>
                    </mesh>
                </geometry>
            </visual>
            <visual name="center_right_headlight_visual">
                <pose frame="">0.485766 -0.0844 0.124431 0 0 -3.14159</pose>
                <geometry>
                    <mesh>
                        <uri>meshes/headlight.dae</uri>
                    </mesh>
                </geometry>
            </visual>
            <visual name="left_headlight_visual">
                <pose frame="">0.461459 0.216803 0.124431 0 0 -3.14159</pose>
                <geometry>
                    <mesh>
                        <uri>meshes/headlight.dae</uri>
                    </mesh>
                </geometry>
            </visual>
            <visual name="marker_visual_1">
                <pose frame="">0.066047 0.212211 0.209188 -3.14159 1.57079 -1.60259</pose>
                <geometry>
                    <mesh>
                        <uri>meshes/led.dae</uri>
                    </mesh>
                </geometry>
            </visual>
            <visual name="marker_visual_2">
                <pose frame="">-0.066047 0.212211 0.209188 -3.14159 1.57079 -1.60259</pose>
                <geometry>
                    <mesh>
                        <uri>meshes/led.dae</uri>
                    </mesh>
                </geometry>
            </visual>
            <visual name="marker_visual_3">
                <pose frame="">-0.42493 0 0.209188 3.14159 1.57079 7e-06</pose>
                <geometry>
                    <mesh>
                        <uri>meshes/led.dae</uri>
                    </mesh>
                </geometry>
            </visual>
            <visual name="marker_visual_4">
                <pose frame="">-0.42493 0.13619 0.209188 3.14159 1.57079 7e-06</pose>
                <geometry>
                    <mesh>
                        <uri>meshes/led.dae</uri>
                    </mesh>
                </geometry>
            </visual>
            <visual name="marker_visual_5">
                <pose frame="">-0.42493 -0.13619 0.209188 3.14159 1.57079 7e-06</pose>
                <geometry>
                    <mesh>
                        <uri>meshes/led.dae</uri>
                    </mesh>
                </geometry>
            </visual>
            <visual name="right_headlight_visual">
                <pose frame="">0.461459 -0.216803 0.124431 0 0 -3.14159</pose>
                <geometry>
                    <mesh>
                        <uri>meshes/headlight.dae</uri>
                    </mesh>
                </geometry>
            </visual>
            <visual name="marker_visual_6">
                <pose frame="">0.066047 -0.212211 0.209188 3.14159 1.57079 1.60259</pose>
                <geometry>
                    <mesh>
                        <uri>meshes/led.dae</uri>
                    </mesh>
                </geometry>
            </visual>
            <visual name="marker_visual_7">
                <pose frame="">-0.066047 -0.212211 0.209188 3.14159 1.57079 1.60259</pose>
                <geometry>
                    <mesh>
                        <uri>meshes/led.dae</uri>
                    </mesh>
                </geometry>
            </visual>
            <visual name="top_plate_visual">
                <pose frame="">0.0812 0 0.245 0 0 0</pose>
                <geometry>
                    <mesh>
                        <uri>meshes/top_plate.dae</uri>
                    </mesh>
                </geometry>
            </visual>
            <visual name="camera_visual">
                <pose>0.43 0 0.26 0 0 0</pose>
                <geometry>
                    <box>
                        <size>0.02 0.02 0.02</size>
                    </box>
                </geometry>
            </visual>
            <sensor name="imu_sensor" type="imu">
                <always_on>1</always_on>
                <update_rate>1</update_rate>
                <visualize>true</visualize>
                <topic>imu</topic>
            </sensor>
            <sensor name="camera_front" type="camera">
                <pose>0.43 0 0.26 0 0 0</pose>
                <always_on>1</always_on>
                <update_rate>5</update_rate>
                <camera name="camera_front">
                    <horizontal_fov>1.0472</horizontal_fov>
                    <image>
                        <width>640</width>
                        <height>480</height>
                        <format>R8G8B8</format>
                    </image>
                    <clip>
                        <near>0.01</near>
                        <far>300</far>
                    </clip>
                </camera>
            </sensor>
            <visual name="laser_visual">
                <pose>0.08 0 0.3 0 0 0</pose>
                <geometry>
                    <cylinder>
                        <radius>0.03</radius>
                        <length>0.1</length>
                    </cylinder>
                </geometry>
            </visual>
            <sensor name='gpu_lidar' type='gpu_lidar'>
                <pose>0.43 0 0.26 0 0 0</pose>
                <topic>/sonar</topic>
                <update_rate>10</update_rate>
                <lidar>
                  <scan>
                    <horizontal>
                      <samples>1</samples>
                      <resolution>1</resolution>
                      <min_angle>0</min_angle>
                      <max_angle>0</max_angle>
                    </horizontal>
                  </scan>
                  <range>
                    <min>0.08</min>
                    <max>10.0</max>
                    <resolution>0.02</resolution>
                  </range>
                </lidar>
                <alwaysOn>1</alwaysOn>
                <visualize>true</visualize>
          </sensor>
        </link>
        <link name="front_left_wheel">
            <pose frame="">0.256 0.2854 0.03282 0 0 0</pose>
            <inertial>
                <mass>2.637</mass>
                <inertia>
                    <ixx>0.02467</ixx>
                    <ixy>0</ixy>
                    <ixz>0</ixz>
                    <iyy>0.04411</iyy>
                    <iyz>0</iyz>
                    <izz>0.02467</izz>
                </inertia>
            </inertial>
            <collision name="collision">
                <pose frame="">0 0 0 -1.5707963267948966 0 0</pose>
                <geometry>
                    <cylinder>
                        <length>0.1143</length>
                        <radius>0.1651</radius>
                    </cylinder>
                </geometry>
                <surface>
                    <friction>
                        <ode>
                            <mu>0.5</mu>
                            <mu2>1</mu2>
                            <slip1>0.00062</slip1>
                            <slip2>0</slip2>
                            <fdir1>0 0 1</fdir1>
                        </ode>
                    </friction>
                </surface>
            </collision>
            <visual name="visual">
                <geometry>
                    <mesh>
                        <uri>meshes/wheel.dae</uri>
                    </mesh>
                </geometry>
            </visual>
        </link>
        <joint name="front_left_wheel_joint" type="revolute">
            <parent>base_link</parent>
            <child>front_left_wheel</child>
            <axis>
                <xyz>0 1 0</xyz>
                <limit>
                    <lower>-1.79769e+308</lower>
                    <upper>+1.79769e+308</upper>
                </limit>
            </axis>
        </joint>
        <link name="front_right_wheel">
            <pose frame="">0.256 -0.2854 0.03282 0 0 0</pose>
            <inertial>
                <mass>2.637</mass>
                <inertia>
                    <ixx>0.02467</ixx>
                    <ixy>0</ixy>
                    <ixz>0</ixz>
                    <iyy>0.04411</iyy>
                    <iyz>0</iyz>
                    <izz>0.02467</izz>
                </inertia>
            </inertial>
            <collision name="collision">
                <pose frame="">0 0 0 -1.5707963267948966 0 0</pose>
                <geometry>
                    <cylinder>
                        <length>0.1143</length>
                        <radius>0.1651</radius>
                    </cylinder>
                </geometry>
                <surface>
                    <friction>
                        <ode>
                            <mu>0.5</mu>
                            <mu2>1</mu2>
                            <slip1>0.00062</slip1>
                            <slip2>0</slip2>
                            <fdir1>0 0 1</fdir1>
                        </ode>
                    </friction>
                </surface>
            </collision>
            <visual name="visual">
                <geometry>
                    <mesh>
                        <uri>meshes/wheel.dae</uri>
                    </mesh>
                </geometry>
            </visual>
        </link>
        <joint name="front_right_wheel_joint" type="revolute">
            <child>front_right_wheel</child>
            <parent>base_link</parent>
            <axis>
                <xyz>0 1 0</xyz>
                <limit>
                    <lower>-1.79769e+308</lower>
                    <upper>+1.79769e+308</upper>
                </limit>
            </axis>
        </joint>
        <link name="rear_left_wheel">
            <pose frame="">-0.256 0.2854 0.03282 0 0 0</pose>
            <inertial>
                <mass>2.637</mass>
                <inertia>
                    <ixx>0.02467</ixx>
                    <ixy>0</ixy>
                    <ixz>0</ixz>
                    <iyy>0.04411</iyy>
                    <iyz>0</iyz>
                    <izz>0.02467</izz>
                </inertia>
            </inertial>
            <collision name="collision">
                <pose frame="">0 0 0 -1.5707963267948966 0 0</pose>
                <geometry>
                    <cylinder>
                        <length>0.1143</length>
                        <radius>0.1651</radius>
                    </cylinder>
                </geometry>
                <surface>
                    <friction>
                        <ode>
                            <mu>0.5</mu>
                            <mu2>1</mu2>
                            <slip1>0.00062</slip1>
                            <slip2>0</slip2>
                            <fdir1>0 0 1</fdir1>
                        </ode>
                    </friction>
                </surface>
            </collision>
            <visual name="visual">
                <geometry>
                    <mesh>
                        <uri>meshes/wheel.dae</uri>
                    </mesh>
                </geometry>
            </visual>
        </link>
        <joint name="rear_left_wheel_joint" type="revolute">
            <parent>base_link</parent>
            <child>rear_left_wheel</child>
            <axis>
                <xyz>0 1 0</xyz>
                <limit>
                    <lower>-1.79769e+308</lower>
                    <upper>+1.79769e+308</upper>
                </limit>
            </axis>
        </joint>
        <link name="rear_right_wheel">
            <pose frame="">-0.256 -0.2854 0.03282 0 0 0</pose>
            <inertial>
                <mass>2.637</mass>
                <inertia>
                    <ixx>0.02467</ixx>
                    <ixy>0</ixy>
                    <ixz>0</ixz>
                    <iyy>0.04411</iyy>
                    <iyz>0</iyz>
                    <izz>0.02467</izz>
                </inertia>
            </inertial>
            <collision name="collision">
                <pose frame="">0 0 0 -1.5707963267948966 0 0</pose>
                <geometry>
                    <cylinder>
                        <length>0.1143</length>
                        <radius>0.1651</radius>
                    </cylinder>
                </geometry>
                <surface>
                    <friction>
                        <ode>
                            <mu>0.5</mu>
                            <mu2>1</mu2>
                            <slip1>0.00062</slip1>
                            <slip2>0</slip2>
                            <fdir1>0 0 1</fdir1>
                        </ode>
                    </friction>
                </surface>
            </collision>
            <visual name="visual">
                <geometry>
                    <mesh>
                        <uri>meshes/wheel.dae</uri>
                    </mesh>
                </geometry>
            </visual>
        </link>
        <joint name="rear_right_wheel_joint" type="revolute">
            <child>rear_right_wheel</child>
            <parent>base_link</parent>
            <axis>
                <xyz>0 1 0</xyz>
                <limit>
                    <lower>-1.79769e+308</lower>
                    <upper>+1.79769e+308</upper>
                </limit>
            </axis>
        </joint>
        <plugin
          filename="libignition-gazebo-diff-drive-system.so"
          name="ignition::gazebo::systems::DiffDrive"
        >
          <left_joint>rear_left_wheel_joint</left_joint>
          <right_joint>rear_right_wheel_joint</right_joint>
          <wheel_separation>3.25</wheel_separation>
          <wheel_radius>1.5</wheel_radius>
          <odom_publish_frequency>1</odom_publish_frequency>
        </plugin>

        <plugin filename="libignition-gazebo-logical-camera-system.so"
            name="ignition::gazebo::systems::LogicalCamera">
        </plugin>

        <plugin
          filename="ignition-gazebo-imu-system"
          name="ignition::gazebo::systems::Imu">
        </plugin>

        <plugin filename="libignition-gazebo-pose-publisher-system.so"
            name="ignition::gazebo::systems::PosePublisher">
            <publish_link_pose>true</publish_link_pose>
            <publish_sensor_pose>false</publish_sensor_pose>
            <publish_collision_pose>false</publish_collision_pose>
            <publish_visual_pose>false</publish_visual_pose>
            <publish_nested_model_pose>true</publish_nested_model_pose>
            <use_pose_vector_msg>true</use_pose_vector_msg>
            <static_publisher>true</static_publisher>
            <static_update_frequency>30</static_update_frequency>
        </plugin>
    </model>
</sdf>
